2023-08-21 12:36:36,855 INFO    StreamThr :2525009 [internal.py:wandb_internal():86] W&B internal server running at pid: 2525009, started at: 2023-08-21 12:36:36.854850
2023-08-21 12:36:36,856 DEBUG   HandlerThread:2525009 [handler.py:handle_request():144] handle_request: status
2023-08-21 12:36:36,858 INFO    WriterThread:2525009 [datastore.py:open_for_write():85] open: /home/cv/Desktop/KD/CLIPPO/wandb/run-20230821_123636-csj2dpwn/run-csj2dpwn.wandb
2023-08-21 12:36:36,858 DEBUG   SenderThread:2525009 [sender.py:send():379] send: header
2023-08-21 12:36:36,914 DEBUG   SenderThread:2525009 [sender.py:send():379] send: run
2023-08-21 12:36:37,579 ERROR   SenderThread:2525009 [internal_api.py:execute():326] 401 response executing GraphQL.
2023-08-21 12:36:37,579 ERROR   SenderThread:2525009 [internal_api.py:execute():327] {"errors":[{"message":"user is not logged in","path":["upsertBucket"],"extensions":{"code":"PERMISSION_ERROR"}}],"data":{"upsertBucket":null}}
2023-08-21 12:36:37,579 ERROR   SenderThread:2525009 [sender.py:send_run():976] The API key you provided is either invalid or missing.  If the `WANDB_API_KEY` environment variable is set, make sure it is correct. Otherwise, to resolve this issue, you may try running the 'wandb login --relogin' command. If you are using a local server, make sure that you're using the correct hostname. If you're not sure, you can try logging in again using the 'wandb login --relogin --host [hostname]' command.(Error 401: Unauthorized)
Traceback (most recent call last):
  File "/home/cv/anaconda3/envs/clippo/lib/python3.8/site-packages/wandb/sdk/lib/retry.py", line 131, in __call__
    result = self._call_fn(*args, **kwargs)
  File "/home/cv/anaconda3/envs/clippo/lib/python3.8/site-packages/wandb/sdk/internal/internal_api.py", line 323, in execute
    return self.client.execute(*args, **kwargs)  # type: ignore
  File "/home/cv/anaconda3/envs/clippo/lib/python3.8/site-packages/wandb/vendor/gql-0.2.0/wandb_gql/client.py", line 52, in execute
    result = self._get_result(document, *args, **kwargs)
  File "/home/cv/anaconda3/envs/clippo/lib/python3.8/site-packages/wandb/vendor/gql-0.2.0/wandb_gql/client.py", line 60, in _get_result
    return self.transport.execute(document, *args, **kwargs)
  File "/home/cv/anaconda3/envs/clippo/lib/python3.8/site-packages/wandb/sdk/lib/gql_request.py", line 56, in execute
    request.raise_for_status()
  File "/home/cv/anaconda3/envs/clippo/lib/python3.8/site-packages/requests/models.py", line 1021, in raise_for_status
    raise HTTPError(http_error_msg, response=self)
requests.exceptions.HTTPError: 401 Client Error: Unauthorized for url: https://api.wandb.ai/graphql

During handling of the above exception, another exception occurred:

Traceback (most recent call last):
  File "/home/cv/anaconda3/envs/clippo/lib/python3.8/site-packages/wandb/sdk/internal/sender.py", line 974, in send_run
    self._init_run(run, config_value_dict)
  File "/home/cv/anaconda3/envs/clippo/lib/python3.8/site-packages/wandb/sdk/internal/sender.py", line 1012, in _init_run
    server_run, inserted, server_messages = self._api.upsert_run(
  File "/home/cv/anaconda3/envs/clippo/lib/python3.8/site-packages/wandb/apis/normalize.py", line 73, in wrapper
    raise err
  File "/home/cv/anaconda3/envs/clippo/lib/python3.8/site-packages/wandb/apis/normalize.py", line 41, in wrapper
    return func(*args, **kwargs)
  File "/home/cv/anaconda3/envs/clippo/lib/python3.8/site-packages/wandb/sdk/internal/internal_api.py", line 1958, in upsert_run
    response = self.gql(
  File "/home/cv/anaconda3/envs/clippo/lib/python3.8/site-packages/wandb/sdk/internal/internal_api.py", line 295, in gql
    ret = self._retry_gql(
  File "/home/cv/anaconda3/envs/clippo/lib/python3.8/site-packages/wandb/sdk/lib/retry.py", line 147, in __call__
    retry_timedelta_triggered = check_retry_fn(e)
  File "/home/cv/anaconda3/envs/clippo/lib/python3.8/site-packages/wandb/util.py", line 956, in check_retry_fn
    return fallback_retry_fn(e)
  File "/home/cv/anaconda3/envs/clippo/lib/python3.8/site-packages/wandb/util.py", line 887, in no_retry_auth
    raise AuthenticationError(
wandb.errors.AuthenticationError: The API key you provided is either invalid or missing.  If the `WANDB_API_KEY` environment variable is set, make sure it is correct. Otherwise, to resolve this issue, you may try running the 'wandb login --relogin' command. If you are using a local server, make sure that you're using the correct hostname. If you're not sure, you can try logging in again using the 'wandb login --relogin --host [hostname]' command.(Error 401: Unauthorized)
2023-08-21 12:36:37,898 DEBUG   HandlerThread:2525009 [handler.py:handle_request():144] handle_request: shutdown
2023-08-21 12:36:37,898 INFO    HandlerThread:2525009 [handler.py:finish():857] shutting down handler
2023-08-21 12:36:37,914 INFO    WriterThread:2525009 [datastore.py:close():294] close: /home/cv/Desktop/KD/CLIPPO/wandb/run-20230821_123636-csj2dpwn/run-csj2dpwn.wandb
2023-08-21 12:36:38,581 INFO    SenderThread:2525009 [sender.py:finish():1552] shutting down sender
